<?xml version="1.0" ?>

<robot xmlns:xacro="http://www.ros.org/wiki/xacro">

  <!-- Link base footprint -->
  <link name="base_footprint"/>
  <!-- Joint base footprint -->
  <joint name="base_joint" type="fixed">
      <parent link="base_footprint" />
      <child link="base_link" />
      <origin xyz="0 0 0.019" rpy="0 0 0" />
  </joint>

<!-- Link base_link -->
  <link name="base_link">
    <inertial>
      <origin xyz="-0.00178426 -0.000464244 0.021065" rpy="0 0 0"/>
      <mass value="1.56734"/>
      <inertia ixx="0.0042106" ixy="1.29827e-06" ixz="0.000258451" iyy="0.0071422" iyz="5.95559e-06" izz="0.00967847"/>
    </inertial>
    <!-- Part base_link -->
    <visual>
      <origin xyz="0 0 0" rpy="0 -0 0"/>
      <geometry>
        <mesh filename="package://slambot_description/assets/base_link.stl"/>
      </geometry>
      <material name="base_link_material">
        <color rgba="1 0 0 1"/>
      </material>
    </visual>
    <collision>
      <origin xyz="0 0 0.051" rpy="0 -0 0"/>
      <geometry>
        <box size="0.216 0.156 0.108"/>
      </geometry>
    </collision>
  </link>

  <!-- Link rear_right_wheel_link -->
  <link name="rear_right_wheel_link">
    <inertial>
      <origin xyz="-9.27276e-19 2.38145e-18 0.0198476" rpy="0 0 0"/>
      <mass value="0.0642702"/>
      <inertia ixx="2.85888e-05" ixy="-1.90555e-11" ixz="0" iyy="2.85888e-05" iyz="0" izz="4.92789e-05"/>
    </inertial>
    <!-- Part rear_right_wheel_link -->
    <visual>
      <origin xyz="0 0 0.032" rpy="-1.5708 -0 0"/>
      <geometry>
        <mesh filename="package://slambot_description/assets/wheel_link.stl"/>
      </geometry>
      <material name="wheel_link_material">
        <color rgba="0.901961 0.901961 0.901961 1"/>
      </material>
    </visual>
    <collision>
      <origin xyz="0 0 0.0185" rpy="0 -0 0"/>
      <geometry>
        <cylinder radius="0.034" length="0.027" />
      </geometry>
    </collision>
  </link>
  <!-- Joint from base_link to rear_right_wheel_link -->
  <joint name="rear_right_wheel_joint" type="continuous">
    <origin xyz="-0.0825 -0.08 0.015" rpy="1.5708 -0 0"/>
    <parent link="base_link"/>
    <child link="rear_right_wheel_link"/>
    <axis xyz="0 0 -1"/>
    <limit effort="100" velocity="100"/>
  </joint>

  <!-- Link front_right_wheel_link -->
  <link name="front_right_wheel_link">
    <inertial>
      <origin xyz="-9.27276e-19 -2.38145e-18 -0.0198476" rpy="0 0 0"/>
      <mass value="0.0642702"/>
      <inertia ixx="2.85888e-05" ixy="1.90555e-11" ixz="0" iyy="2.85888e-05" iyz="0" izz="4.92789e-05"/>
    </inertial>
    <!-- Part front_right_wheel_link -->
    <visual>
      <origin xyz="0 0 -0.032" rpy="1.5708 -0 0"/>
      <geometry>
        <mesh filename="package://slambot_description/assets/wheel_link.stl"/>
      </geometry>
      <material name="wheel_link_2_material">
        <color rgba="0.901961 0.901961 0.901961 1"/>
      </material>
    </visual>
    <collision>
      <origin xyz="0 0 -0.0185" rpy="0 -0 0"/>
      <geometry>
        <cylinder radius="0.034" length="0.027" />
      </geometry>
    </collision>
  </link>
  <!-- Joint from base_link to front_right_wheel_link -->
  <joint name="front_right_wheel_joint" type="continuous">
    <origin xyz="0.0825 -0.08 0.015" rpy="-1.5708 -0 0"/>
    <parent link="base_link"/>
    <child link="front_right_wheel_link"/>
    <axis xyz="0 0 1"/>
    <limit effort="100" velocity="100"/>
  </joint>

  <!-- Link front_left_wheel_link -->
  <link name="front_left_wheel_link">
    <inertial>
      <origin xyz="-9.27276e-19 -2.38145e-18 -0.0198476" rpy="0 0 0"/>
      <mass value="0.0642702"/>
      <inertia ixx="2.85888e-05" ixy="1.90555e-11" ixz="0" iyy="2.85888e-05" iyz="0" izz="4.92789e-05"/>
    </inertial>
    <!-- Part front_left_wheel_link -->
    <visual>
      <origin xyz="0 0 -0.032" rpy="1.5708 -0 0"/>
      <geometry>
        <mesh filename="package://slambot_description/assets/wheel_link.stl"/>
      </geometry>
      <material name="wheel_link_3_material">
        <color rgba="0.901961 0.901961 0.901961 1"/>
      </material>
    </visual>
    <collision>
      <origin xyz="0 0 -0.0185" rpy="0 -0 0"/>
      <geometry>
        <cylinder radius="0.034" length="0.027" />
      </geometry>
    </collision>
  </link>
  <!-- Joint from base_link to front_left_wheel_link -->
  <joint name="front_left_wheel_joint" type="continuous">
    <origin xyz="0.0825 0.08 0.015" rpy="1.5708 -0 0"/>
    <parent link="base_link"/>
    <child link="front_left_wheel_link"/>
    <axis xyz="0 0 -1"/>
    <limit effort="100" velocity="100"/>
  </joint>

  <!-- Link rear_left_wheel_link -->
  <link name="rear_left_wheel_link">
    <inertial>
      <origin xyz="-9.27276e-19 2.38145e-18 0.0198476" rpy="0 0 0"/>
      <mass value="0.0642702"/>
      <inertia ixx="2.85888e-05" ixy="-1.90555e-11" ixz="0" iyy="2.85888e-05" iyz="0" izz="4.92789e-05"/>
    </inertial>
    <!-- Part rear_left_wheel_link -->
    <visual>
      <origin xyz="0 0 0.032" rpy="-1.5708 -0 0"/>
      <geometry>
        <mesh filename="package://slambot_description/assets/wheel_link.stl"/>
      </geometry>
      <material name="wheel_link_4_material">
        <color rgba="0.901961 0.901961 0.901961 1"/>
      </material>
    </visual>
    <collision>
      <origin xyz="0 0 0.0185" rpy="0 -0 0"/>
      <geometry>
        <cylinder radius="0.034" length="0.027" />
      </geometry>
    </collision>
  </link>
  <!-- Joint from base_link to rear_left_wheel_link -->
  <joint name="rear_left_wheel_joint" type="continuous">
    <origin xyz="-0.0825 0.08 0.015" rpy="-1.5708 -0 0"/>
    <parent link="base_link"/>
    <child link="rear_left_wheel_link"/>
    <axis xyz="0 0 1"/>
    <limit effort="100" velocity="100"/>
  </joint>


</robot>