<?xml version="1.0"?>
<robot xmlns:xacro="http://www.ros.org/wiki/xacro"  name="robot">

<xacro:include filename="$(find kc_vision_description)/urdf/project_visionkc.gazebo" />


  <material name="silver">
    <color rgba="0.700 0.700 0.700 1.000"/>
  </material>

  <material name="aluminium">
    <color rgba="0.5 0.5 0.5 1.0"/>
  </material>

  <material name="rubber_black">
    <color rgba="0.1 0.1 0.1 1.0"/>
  </material>

  <material name="white">
    <color rgba="1.0 1.0 1.0 1.0"/>
  </material>

  <material name="black_pure">
    <color rgba="0.0 0.0 0.0 1.0"/>
  </material>

  <material name="red">
    <color rgba="0.8 0.0 0.0 1.0"/>
  </material>

  <material name="yellow">
    <color rgba="0.8 0.8 0.0 1.0"/>
  </material>

  <material name="green">
    <color rgba="0.0 0.8 0.0 1.0"/>
  </material>

  <material name="blue">
    <color rgba="0.0 0.0 0.8 1.0"/>
  </material>

  <material name="sky_blue">
    <color rgba="0.53 0.81 0.92 1.0"/>
  </material>

  <material name="brown">
    <color rgba="0.59 0.29 0.0 1.0"/>
  </material>

  <material name="pink">
    <color rgba="1.0 0.75 0.79 1.0"/>
  </material>

  <material name="ash">
    <color rgba="0.7 0.7 0.7 1.0"/>
  </material>
 
  

<!-- BASE_FOOTPRINT -->
<link name="base_footprint"/>  

<joint name="base_footprint_joint" type="fixed">
    <parent link="base_footprint"/>
    <child link="base_link"/>
    <origin xyz="0 0 -0.2" rpy="0 0 0"/>
</joint>



<link name="base_link">
  <inertial>
    <origin xyz="0.014165443507547821 1.6805892300757203e-10 -0.007976017196994426" rpy="0 0 0"/>
    <mass value="3.0557429944760086"/>
    <inertia ixx="0.017971" iyy="0.059186" izz="0.07452" ixy="0.0" iyz="0.0" ixz="-0.00276"/>
  </inertial>
  <visual>
    <origin xyz="0 0 0" rpy="0 0 0"/>
    <geometry>
      <mesh filename="file://$(find kc_vision)/meshes/base_link.stl" scale="0.001 0.001 0.001"/>
    </geometry>
    <material name="white"/>
  </visual>
  <collision>
    <origin xyz="0 0 0" rpy="0 0 0"/>
    <geometry>
      <mesh filename="file://$(find kc_vision)/meshes/base_link.stl" scale="0.001 0.001 0.001"/>
    </geometry>
  </collision>
</link>


<link name="A7_-_DC_Geared_Motor_v1_1">
  <inertial>
    <origin xyz="2.941350840945933e-07 -0.02716453886229528 -0.00020823122710950104" rpy="0 0 0"/>
    <mass value="0.14684733943099942"/>
    <inertia ixx="6.8e-05" iyy="2e-05" izz="6.8e-05" ixy="-0.0" iyz="1e-06" ixz="0.0"/>
  </inertial>
  <visual>
    <origin xyz="-0.219081 -0.16 0.065" rpy="0 0 0"/>
    <geometry>
      <mesh filename="file://$(find kc_vision)/meshes/A7_-_DC_Geared_Motor_v1_1.stl" scale="0.001 0.001 0.001"/>
    </geometry>
    <material name="black_pure"/>
  </visual>
  <collision>
    <origin xyz="-0.219081 -0.16 0.065" rpy="0 0 0"/>
    <geometry>
      <mesh filename="file://$(find kc_vision)/meshes/A7_-_DC_Geared_Motor_v1_1.stl" scale="0.001 0.001 0.001"/>
    </geometry>
  </collision>
</link>

<link name="right_Omni_Wheel__1">
  <inertial>
    <origin xyz="2.929291573472437e-07 -0.016399999058894277 -3.443219875887138e-10" rpy="0 0 0"/>
    <mass value="0.3535254527736422"/>
    <inertia ixx="0.000552" iyy="0.001032" izz="0.000552" ixy="-0.0" iyz="-0.0" ixz="0.0"/>
  </inertial>
  <visual>
    <origin xyz="-0.219081 0.1968 0.072" rpy="0 0 0"/>
    <geometry>
      <mesh filename="file://$(find kc_vision)/meshes/right_Omni_Wheel__1.stl" scale="0.001 0.001 0.001"/>
    </geometry>
    <material name="rubber_black"/>
  </visual>
  <collision>
    <origin xyz="-0.219081 0.1968 0.072" rpy="0 0 0"/>
    <geometry>
      <mesh filename="file://$(find kc_vision)/meshes/right_Omni_Wheel__1.stl" scale="0.001 0.001 0.001"/>
    </geometry>
  </collision>
</link>

<link name="left_Omni_Wheel_v1__1__1">
  <inertial>
    <origin xyz="2.9300848389257617e-07 0.016400000941105553 5.509969980277418e-10" rpy="0 0 0"/>
    <mass value="0.3535254527736422"/>
    <inertia ixx="0.000552" iyy="0.001032" izz="0.000552" ixy="-0.0" iyz="0.0" ixz="-0.0"/>
  </inertial>
  <visual>
    <origin xyz="-0.219081 -0.1968 0.072" rpy="0 0 0"/>
    <geometry>
      <mesh filename="file://$(find kc_vision)/meshes/left_Omni_Wheel_v1__1__1.stl" scale="0.001 0.001 0.001"/>
    </geometry>
    <material name="rubber_black"/>
  </visual>
  <collision>
    <origin xyz="-0.219081 -0.1968 0.072" rpy="0 0 0"/>
    <geometry>
      <mesh filename="file://$(find kc_vision)/meshes/left_Omni_Wheel_v1__1__1.stl" scale="0.001 0.001 0.001"/>
    </geometry>
  </collision>
</link>

<link name="left_Wheel_Rim_1">
  <inertial>
    <origin xyz="-2.718639801335687e-07 0.02106386990559933 3.738353611393297e-08" rpy="0 0 0"/>
    <mass value="0.07234824268237931"/>
    <inertia ixx="5.7e-05" iyy="0.000104" izz="5.7e-05" ixy="-0.0" iyz="-0.0" ixz="-0.0"/>
  </inertial>
  <visual>
    <origin xyz="0.219081 -0.1968 0.072" rpy="0 0 0"/>
    <geometry>
      <mesh filename="file://$(find kc_vision)/meshes/left_Wheel_Rim_1.stl" scale="0.001 0.001 0.001"/>
    </geometry>
    <material name="white"/>
  </visual>
  <collision>
    <origin xyz="0.219081 -0.1968 0.072" rpy="0 0 0"/>
    <geometry>
      <mesh filename="file://$(find kc_vision)/meshes/left_Wheel_Rim_1.stl" scale="0.001 0.001 0.001"/>
    </geometry>
  </collision>
</link>

<link name="left_Wheel_tire_1">
  <inertial>
    <origin xyz="0.06826070586493341 0.2152667498797558 -0.22027499999999997" rpy="0 0 0"/>
    <mass value="0.3007431061477273"/>
    <inertia ixx="0.000619" iyy="0.001184" izz="0.000619" ixy="0.0" iyz="-0.0" ixz="-0.0"/>
  </inertial>
  <visual>
    <origin xyz="0.287342 -0.003 -0.148275" rpy="0 0 0"/>
    <geometry>
      <mesh filename="file://$(find kc_vision)/meshes/left_Wheel_tire_1.stl" scale="0.001 0.001 0.001"/>
    </geometry>
    <material name="rubber_black"/>
  </visual>
  <collision>
    <origin xyz="0.287342 -0.003 -0.148275" rpy="0 0 0"/>
    <geometry>
      <mesh filename="file://$(find kc_vision)/meshes/left_Wheel_tire_1.stl" scale="0.001 0.001 0.001"/>
    </geometry>
  </collision>
</link>

<link name="right_Wheel_Rim_1">
  <inertial>
    <origin xyz="-3.116989502893741e-07 -0.021063869905599136 -3.9812561497543086e-08" rpy="0 0 0"/>
    <mass value="0.07234824268237931"/>
    <inertia ixx="5.7e-05" iyy="0.000104" izz="5.7e-05" ixy="-0.0" iyz="-0.0" ixz="0.0"/>
  </inertial>
  <visual>
    <origin xyz="0.219081 0.1968 0.072" rpy="0 0 0"/>
    <geometry>
      <mesh filename="file://$(find kc_vision)/meshes/right_Wheel_Rim_1.stl" scale="0.001 0.001 0.001"/>
    </geometry>
    <material name="white"/>
  </visual>
  <collision>
    <origin xyz="0.219081 0.1968 0.072" rpy="0 0 0"/>
    <geometry>
      <mesh filename="file://$(find kc_vision)/meshes/right_Wheel_Rim_1.stl" scale="0.001 0.001 0.001"/>
    </geometry>
  </collision>
</link>

<link name="right_Wheel_Tire_1">
  <inertial>
    <origin xyz="0.21908170586493367 0.2452902467369124 0.07200000000000067" rpy="0 0 0"/>
    <mass value="0.3007431061477273"/>
    <inertia ixx="0.000619" iyy="0.001184" izz="0.000619" ixy="0.0" iyz="0.0" ixz="0.0"/>
  </inertial>
  <visual>
    <origin xyz="0.438163 0.4636 0.144" rpy="0 0 0"/>
    <geometry>
      <mesh filename="file://$(find kc_vision)/meshes/right_Wheel_Tire_1.stl" scale="0.001 0.001 0.001"/>
    </geometry>
    <material name="rubber_black"/>
  </visual>
  <collision>
    <origin xyz="0.438163 0.4636 0.144" rpy="0 0 0"/>
    <geometry>
      <mesh filename="file://$(find kc_vision)/meshes/right_Wheel_Tire_1.stl" scale="0.001 0.001 0.001"/>
    </geometry>
  </collision>
</link>

<link name="A7_-_DC_Geared_Motor_v1_Mirror__1">
  <inertial>
    <origin xyz="2.941350840945933e-07 0.027164538862295112 -0.00020823122710950104" rpy="0 0 0"/>
    <mass value="0.14684733943099942"/>
    <inertia ixx="6.8e-05" iyy="2e-05" izz="6.8e-05" ixy="0.0" iyz="-1e-06" ixz="0.0"/>
  </inertial>
  <visual>
    <origin xyz="-0.219081 0.16 0.065" rpy="0 0 0"/>
    <geometry>
      <mesh filename="file://$(find kc_vision)/meshes/A7_-_DC_Geared_Motor_v1_Mirror__1.stl" scale="0.001 0.001 0.001"/>
    </geometry>
    <material name="black_pure"/>
  </visual>
  <collision>
    <origin xyz="-0.219081 0.16 0.065" rpy="0 0 0"/>
    <geometry>
      <mesh filename="file://$(find kc_vision)/meshes/A7_-_DC_Geared_Motor_v1_Mirror__1.stl" scale="0.001 0.001 0.001"/>
    </geometry>
  </collision>
</link>

<link name="A7_-_DC_Geared_Motor_v1_Mirror___1__1">
  <inertial>
    <origin xyz="-2.941350841501045e-07 -0.02716453886229528 -0.00020823122710950104" rpy="0 0 0"/>
    <mass value="0.14684733943099942"/>
    <inertia ixx="6.8e-05" iyy="2e-05" izz="6.8e-05" ixy="0.0" iyz="1e-06" ixz="-0.0"/>
  </inertial>
  <visual>
    <origin xyz="0.219081 -0.16 0.065" rpy="0 0 0"/>
    <geometry>
      <mesh filename="file://$(find kc_vision)/meshes/A7_-_DC_Geared_Motor_v1_Mirror___1__1.stl" scale="0.001 0.001 0.001"/>
    </geometry>
    <material name="black_pure"/>
  </visual>
  <collision>
    <origin xyz="0.219081 -0.16 0.065" rpy="0 0 0"/>
    <geometry>
      <mesh filename="file://$(find kc_vision)/meshes/A7_-_DC_Geared_Motor_v1_Mirror___1__1.stl" scale="0.001 0.001 0.001"/>
    </geometry>
  </collision>
</link>

<link name="A7_-_DC_Geared_Motor_v1_Mirror__Mirror__1">
  <inertial>
    <origin xyz="-2.941350841223489e-07 0.027164538862295168 -0.00020823122710950104" rpy="0 0 0"/>
    <mass value="0.14684733943099942"/>
    <inertia ixx="6.8e-05" iyy="2e-05" izz="6.8e-05" ixy="-0.0" iyz="-1e-06" ixz="-0.0"/>
  </inertial>
  <visual>
    <origin xyz="0.219081 0.16 0.065" rpy="0 0 0"/>
    <geometry>
      <mesh filename="file://$(find kc_vision)/meshes/A7_-_DC_Geared_Motor_v1_Mirror__Mirror__1.stl" scale="0.001 0.001 0.001"/>
    </geometry>
    <material name="black_pure"/>
  </visual>
  <collision>
    <origin xyz="0.219081 0.16 0.065" rpy="0 0 0"/>
    <geometry>
      <mesh filename="file://$(find kc_vision)/meshes/A7_-_DC_Geared_Motor_v1_Mirror__Mirror__1.stl" scale="0.001 0.001 0.001"/>
    </geometry>
  </collision>
</link>




<link name="camera_1">
  <inertial>
    <origin xyz="0.0050000000000000044 1.120650486390323e-34 -1.734723475976807e-18" rpy="0 0 0"/>
    <mass value="0.003975"/>
    <inertia ixx="0.0" iyy="0.0" izz="0.0" ixy="0.0" iyz="0.0" ixz="0.0"/>
  </inertial>
  <visual>
    <origin xyz="-0.24 -0.0 -0.013" rpy="0 0 0"/>
    <geometry>
      <mesh filename="file://$(find kc_vision)/meshes/camera_1.stl" scale="0.001 0.001 0.001"/>
    </geometry>
    <material name="yellow"/>
  </visual>
  <collision>
    <origin xyz="-0.24 -0.0 -0.013" rpy="0 0 0"/>
    <geometry>
      <mesh filename="file://$(find kc_vision)/meshes/camera_1.stl" scale="0.001 0.001 0.001"/>
    </geometry>
  </collision>
</link>

<!-- <link name="150mm_Cutting_disc_holder_v4_1">
  <inertial>
    <origin xyz="3.3767680479579454e-07 -5.093143830025162e-08 -0.01163042893502509" rpy="0 0 0"/>
    <mass value="0.12262133652486505"/>
    <inertia ixx="0.000151" iyy="0.000151" izz="0.000269" ixy="-0.0" iyz="0.0" ixz="-0.0"/>
  </inertial>
  <visual>
    <origin xyz="0.046371 -0.0 0.054" rpy="0 0 0"/>
    <geometry>
      <mesh filename="file://$(find kc_vision)/meshes/150mm_Cutting_disc_holder_v4_1.stl" scale="0.001 0.001 0.001"/>
    </geometry>
    <material name="green"/>
  </visual>
  <collision>
    <origin xyz="0.046371 -0.0 0.054" rpy="0 0 0"/>
    <geometry>
      <mesh filename="file://$(find kc_vision)/meshes/150mm_Cutting_disc_holder_v4_1.stl" scale="0.001 0.001 0.001"/>
    </geometry>
  </collision>
</link> -->

<link name="imu_sensor_TM171__1">
  <inertial>
    <origin xyz="0.030118349654625846 -0.0003586145406981709 0.005788140886370831" rpy="0 0 0"/>
    <mass value="0.0850709285150727"/>
    <inertia ixx="8e-06" iyy="8e-06" izz="1.3e-05" ixy="0.0" iyz="-0.0" ixz="0.0"/>
  </inertial>
  <visual>
    <origin xyz="-0.027243 -0.0 -0.003" rpy="0 0 0"/>
    <geometry>
      <mesh filename="file://$(find kc_vision)/meshes/imu_sensor_TM171__1.stl" scale="0.001 0.001 0.001"/>
    </geometry>
    <material name="blue"/>
  </visual>
  <collision>
    <origin xyz="-0.027243 -0.0 -0.003" rpy="0 0 0"/>
    <geometry>
      <mesh filename="file://$(find kc_vision)/meshes/imu_sensor_TM171__1.stl" scale="0.001 0.001 0.001"/>
    </geometry>
  </collision>
</link>

<joint name="Rigid 1" type="fixed">
  <origin xyz="0.219081 0.16 -0.065" rpy="0 0 0"/>
  <parent link="base_link"/>
  <child link="A7_-_DC_Geared_Motor_v1_1"/>
</joint>

<joint name="Revolute 2" type="continuous">
  <origin xyz="0.0 -0.0368 -0.007" rpy="0 0 0"/>
  <parent link="A7_-_DC_Geared_Motor_v1_Mirror__1"/>
  <child link="right_Omni_Wheel__1"/>
  <axis xyz="-0.0 1.0 0.0"/>
</joint>

<joint name="Revolute 3" type="continuous">
  <origin xyz="0.0 0.0368 -0.007" rpy="0 0 0"/>
  <parent link="A7_-_DC_Geared_Motor_v1_1"/>
  <child link="left_Omni_Wheel_v1__1__1"/>
  <axis xyz="0.0 1.0 0.0"/>
</joint>

<joint name="Revolute 4" type="continuous">
  <origin xyz="0.0 0.0368 -0.007" rpy="0 0 0"/>
  <parent link="A7_-_DC_Geared_Motor_v1_Mirror___1__1"/>
  <child link="left_Wheel_Rim_1"/>
  <axis xyz="0.0 1.0 0.0"/>
</joint>

<joint name="Rigid 5" type="fixed">
  <origin xyz="-0.068261 -0.1938 0.220275" rpy="0 0 0"/>
  <parent link="left_Wheel_Rim_1"/>
  <child link="left_Wheel_tire_1"/>
</joint>

<joint name="Revolute 6" type="continuous">
  <origin xyz="0.0 -0.0368 -0.007" rpy="0 0 0"/>
  <parent link="A7_-_DC_Geared_Motor_v1_Mirror__Mirror__1"/>
  <child link="right_Wheel_Rim_1"/>
  <axis xyz="0.0 1.0 0.0"/>
</joint>

<joint name="Rigid 7" type="fixed">
  <origin xyz="-0.219082 -0.2668 -0.072" rpy="0 0 0"/>
  <parent link="right_Wheel_Rim_1"/>
  <child link="right_Wheel_Tire_1"/>
</joint>

<joint name="Rigid 8" type="fixed">
  <origin xyz="0.219081 -0.16 -0.065" rpy="0 0 0"/>
  <parent link="base_link"/>
  <child link="A7_-_DC_Geared_Motor_v1_Mirror__1"/>
</joint>

<joint name="Rigid 9" type="fixed">
  <origin xyz="-0.219081 0.16 -0.065" rpy="0 0 0"/>
  <parent link="base_link"/>
  <child link="A7_-_DC_Geared_Motor_v1_Mirror___1__1"/>
</joint>

<joint name="Rigid 10" type="fixed">
  <origin xyz="-0.219081 -0.16 -0.065" rpy="0 0 0"/>
  <parent link="base_link"/>
  <child link="A7_-_DC_Geared_Motor_v1_Mirror__Mirror__1"/>
</joint>


<joint name="Rigid 12" type="fixed">
  <origin xyz="0.24 0.0 0.013" rpy="0 0 0"/>
  <parent link="base_link"/>
  <child link="camera_1"/>
</joint>

<!-- <joint name="Revolute 13" type="fixed">
  <origin xyz="-0.046371 0.0 -0.054" rpy="0 0 0"/>
  <parent link="base_link"/>
  <child link="150mm_Cutting_disc_holder_v4_1"/>
  
</joint> -->

<joint name="Rigid 14" type="fixed">
  <origin xyz="0.027243 0.0 0.003" rpy="0 0 0"/>
  <parent link="base_link"/>
  <child link="imu_sensor_TM171__1"/>
</joint>

</robot>