<?xml version="1.0" ?>
<robot name="kc" xmlns:xacro="http://www.ros.org/wiki/xacro">



  <material name="silver">
    <color rgba="0.700 0.700 0.700 1.000"/>
  </material>

  <material name="aluminium">
    <color rgba="0.5 0.5 0.5 1.0"/>
  </material>

  <material name="rubber_black">
    <color rgba="0.1 0.1 0.1 1.0"/>
  </material>

  <material name="white">
    <color rgba="1.0 1.0 1.0 1.0"/>
  </material>

  <material name="black">
    <color rgba="0.0 0.0 0.0 1.0"/>
  </material> 

  <material name="red">
    <color rgba="0.8 0.0 0.0 1.0"/>
  </material>

  <material name="yellow">
    <color rgba="0.8 0.8 0.0 1.0"/>
  </material>

  <material name="green">
    <color rgba="0.0 0.8 0.0 1.0"/>
  </material>

  <material name="blue">
    <color rgba="0.0 0.0 0.8 1.0"/>
  </material>

  <material name="sky_blue">
    <color rgba="0.53 0.81 0.92 1.0"/>
  </material>

  <material name="brown">
    <color rgba="0.59 0.29 0.0 1.0"/>
  </material>

  <material name="pink">
    <color rgba="1.0 0.75 0.79 1.0"/>
  </material>

  <material name="ash">
    <color rgba="0.7 0.7 0.7 1.0"/>
  </material>


<joint name="base_joint" type="fixed">
    <parent link="base_footprint"/>
    <child link="base_link"/>
    <origin xyz="0 0 0.05" rpy="0 0 0"/> 
</joint>
 
<link name="base_link">
  <inertial>
    <origin xyz="-0.03364661034167416 -4.764838969793257e-16 0.06884991716069974" rpy="0 0 0"/>
    <mass value="1.649170994682965"/>
    <inertia ixx="0.016084" iyy="0.018228" izz="0.032312" ixy="0.0" iyz="0.0" ixz="0.001026"/>
  </inertial>
  
  <visual>
    <origin xyz="0 0 0" rpy="3.14159 0 0"/>
    <geometry>
      <mesh filename="file://$(find kc_vision_description)/meshes/base_link.stl" scale="0.001 0.001 0.001"/>
    </geometry>
    <material name="white"/>
  </visual>
  
  <collision>
    <origin xyz="0 0 0.051" rpy="3.14159 0 0"/>
    <geometry>
      <mesh filename="file://$(find kc_vision_description)/meshes/base_link.stl" scale="0.001 0.001 0.001"/>
    </geometry>
  </collision>
</link>

<link name="lidar_link">
  <inertial>
    <origin xyz="0.0 0.0 0.017499999999999988" rpy="0 0 0"/>
    <mass value="0.1048977787033632"/>
    <inertia ixx="3.4e-05" iyy="3.4e-05" izz="4.7e-05" ixy="-0.0" iyz="0.0" ixz="-0.0"/>
  </inertial>
  <visual>
    <origin xyz="-0.13 -0.0 -0.099" rpy="0 0 0"/>
    <geometry>
      <mesh filename="file://$(find kc_vision_description)/meshes/lidar_link_1.stl" scale="0.001 0.001 0.001"/>
    </geometry>
    <material name="yellow"/>
  </visual>
  <collision>
    <origin xyz="-0.13 -0.0 -0.099" rpy="0 0 0"/>
    <geometry>
      <mesh filename="file://$(find kc_vision_description)/meshes/lidar_link_1.stl" scale="0.001 0.001 0.001"/>
    </geometry>
  </collision>
</link>

<link name="camera_link">
  <inertial>
    <origin xyz="0.0050000000000000044 0.0 1.3877787807814457e-17" rpy="0 0 0"/>
    <mass value="0.005342400159215928"/>
    <inertia ixx="0.0" iyy="0.0" izz="0.0" ixy="-0.0" iyz="0.0" ixz="0.0"/>
  </inertial>
  <visual>
    <origin xyz="-0.16 -0.0 -0.089" rpy="0 0 0"/>
    <geometry>
      <mesh filename="file://$(find kc_vision_description)/meshes/camera_1.stl" scale="0.001 0.001 0.001"/>
    </geometry>
    <material name="red"/>
  </visual>
  <collision>
    <origin xyz="-0.16 -0.0 -0.089" rpy="0 0 0"/>
    <geometry>
      <mesh filename="file://$(find kc_vision_description)/meshes/camera_1.stl" scale="0.001 0.001 0.001"/>
    </geometry>
  </collision>
</link>

<link name="left_A7_-_DC_Geared_Motor_1">
  <inertial>
    <origin xyz="1.7430501486614958e-14 -0.02716453886229528 -0.00020823122710948716" rpy="0 0 0"/>
    <mass value="0.057651177702540524"/>
    <inertia ixx="2.7e-05" iyy="8e-06" izz="2.7e-05" ixy="-0.0" iyz="0.0" ixz="0.0"/>
  </inertial>
  <visual>
    <origin xyz="0.138 -0.156 -0.044" rpy="0 0 0"/>
    <geometry>
      <mesh filename="file://$(find kc_vision_description)/meshes/left_A7_-_DC_Geared_Motor_1.stl" scale="0.001 0.001 0.001"/>
    </geometry>
    <material name="black"/>
  </visual>
  <collision>
    <origin xyz="0.138 -0.156 -0.044" rpy="0 0 0"/>
    <geometry>
      <mesh filename="file://$(find kc_vision_description)/meshes/left_A7_-_DC_Geared_Motor_1.stl" scale="0.001 0.001 0.001"/>
    </geometry>
  </collision>
</link>

<link name="A7_-_DC_Geared_Motor_v1__1__1">
  <inertial>
    <origin xyz="-1.7291723608536813e-14 0.027164538862295307 -0.00020823122710954267" rpy="0 0 0"/>
    <mass value="0.057651177702540524"/>
    <inertia ixx="2.7e-05" iyy="8e-06" izz="2.7e-05" ixy="-0.0" iyz="-0.0" ixz="-0.0"/>
  </inertial>
  <visual>
    <origin xyz="0.138 0.156 -0.044" rpy="0 0 0"/>
    <geometry>
      <mesh filename="file://$(find kc_vision_description)/meshes/A7_-_DC_Geared_Motor_v1__1__1.stl" scale="0.001 0.001 0.001"/>
    </geometry>
    <material name="black"/>
  </visual>
  <collision>
    <origin xyz="0.138 0.156 -0.044" rpy="0 0 0"/>
    <geometry>
      <mesh filename="file://$(find kc_vision_description)/meshes/A7_-_DC_Geared_Motor_v1__1__1.stl" scale="0.001 0.001 0.001"/>
    </geometry>
  </collision>
</link>

<link name="Wheel_Rim_s_v1_1">
  <inertial>
    <origin xyz="-3.9087346026533965e-08 -0.021063869905599192 -1.9123532306319913e-08" rpy="0 0 0"/>
    <mass value="0.08246143789604524"/>
    <inertia ixx="6.5e-05" iyy="0.000119" izz="6.5e-05" ixy="-0.0" iyz="-0.0" ixz="-0.0"/>
  </inertial>
  <visual>
    <origin xyz="0.138 0.1928 -0.037" rpy="0 0 0"/>
    <geometry>
      <mesh filename="file://$(find kc_vision_description)/meshes/Wheel_Rim_s_v1_1.stl" scale="0.001 0.001 0.001"/>
    </geometry>
    <material name="white"/>
  </visual>
  <collision>
    <origin xyz="0.138 0.1928 -0.037" rpy="0 0 0"/>
    <geometry>
      <mesh filename="file://$(find kc_vision_description)/meshes/Wheel_Rim_s_v1_1.stl" scale="0.001 0.001 0.001"/>
    </geometry>
  </collision>
</link>

<link name="Wheel_Rim_s_v1__1__1">
  <inertial>
    <origin xyz="4.342273185464762e-08 0.021063869905599303 -2.827792673631979e-09" rpy="0 0 0"/>
    <mass value="0.08246143789604524"/>
    <inertia ixx="6.5e-05" iyy="0.000119" izz="6.5e-05" ixy="-0.0" iyz="-0.0" ixz="0.0"/>
  </inertial>
  <visual>
    <origin xyz="0.138 -0.1928 -0.037" rpy="0 0 0"/>
    <geometry>
      <mesh filename="file://$(find kc_vision_description)/meshes/Wheel_Rim_s_v1__1__1.stl" scale="0.001 0.001 0.001"/>
    </geometry>
    <material name="white"/>
  </visual>
  <collision>
    <origin xyz="0.138 -0.1928 -0.037" rpy="0 0 0"/>
    <geometry>
      <mesh filename="file://$(find kc_vision_description)/meshes/Wheel_Rim_s_v1__1__1.stl" scale="0.001 0.001 0.001"/>
    </geometry>
  </collision>
</link>

<link name="Wheel_Tire_ipt_v1_1">
  <inertial>
    <origin xyz="-4.163336342344337e-16 -0.014033250120242785 -1.942890293094024e-16" rpy="0 0 0"/>
    <mass value="0.30074310614732785"/>
    <inertia ixx="0.000619" iyy="0.001184" izz="0.000619" ixy="0.0" iyz="0.0" ixz="-0.0"/>
  </inertial>
  <visual>
    <origin xyz="0.138 0.2043 -0.037" rpy="0 0 0"/>
    <geometry>
      <mesh filename="file://$(find kc_vision_description)/meshes/Wheel_Tire_ipt_v1_1.stl" scale="0.001 0.001 0.001"/>
    </geometry>
    <material name="black"/>
  </visual>
  <collision>
    <origin xyz="0.138 0.2043 -0.037" rpy="0 0 0"/>
    <geometry>
      <mesh filename="file://$(find kc_vision_description)/meshes/Wheel_Tire_ipt_v1_1.stl" scale="0.001 0.001 0.001"/>
    </geometry>
  </collision>
</link>

<link name="Wheel_Tire_ipt_v1__1__1">
  <inertial>
    <origin xyz="-1.6653345369377348e-16 0.013990246736913736 2.636779683484747e-16" rpy="0 0 0"/>
    <mass value="0.30074310614732785"/>
    <inertia ixx="0.000619" iyy="0.001184" izz="0.000619" ixy="0.0" iyz="0.0" ixz="-0.0"/>
  </inertial>
  <visual>
    <origin xyz="0.138 -0.2043 -0.037" rpy="0 0 0"/>
    <geometry>
      <mesh filename="file://$(find kc_vision_description)/meshes/Wheel_Tire_ipt_v1__1__1.stl" scale="0.001 0.001 0.001"/>
    </geometry>
    <material name="black"/>
  </visual>
  <collision>
    <origin xyz="0.138 -0.2043 -0.037" rpy="0 0 0"/>
    <geometry>
      <mesh filename="file://$(find kc_vision_description)/meshes/Wheel_Tire_ipt_v1__1__1.stl" scale="0.001 0.001 0.001"/>
    </geometry>
  </collision>
</link>

<link name="imu_link">
  <inertial>
    <origin xyz="0.03011850314276346 -0.0003586145406981709 -0.06921185911362918" rpy="0 0 0"/>
    <mass value="0.011487284614774149"/>
    <inertia ixx="1e-06" iyy="1e-06" izz="2e-06" ixy="0.0" iyz="-0.0" ixz="0.0"/>
  </inertial>
  <visual>
    <origin xyz="0.165 -0.0 -0.154" rpy="0 0 0"/>
    <geometry>
      <mesh filename="file://$(find kc_vision_description)/meshes/imu_link_1.stl" scale="0.001 0.001 0.001"/>
    </geometry>
    <material name="green"/>
  </visual>
  <collision>
    <origin xyz="0.165 -0.0 -0.154" rpy="0 0 0"/>
    <geometry>
      <mesh filename="file://$(find kc_vision_description)/meshes/imu_link_1.stl" scale="0.001 0.001 0.001"/>
    </geometry>
  </collision>
</link>

<link name="gps_link">
  <inertial>
    <origin xyz="-0.0407242334885094 5.4323224457475116e-05 -0.07001241807898116" rpy="0 0 0"/>
    <mass value="0.016695520146201126"/>
    <inertia ixx="1e-06" iyy="1e-06" izz="1e-06" ixy="0.0" iyz="0.0" ixz="0.0"/>
  </inertial>
  <visual>
    <origin xyz="-0.1 -0.0 -0.154" rpy="0 0 0"/>
    <geometry>
      <mesh filename="file://$(find kc_vision_description)/meshes/gps_v1_1.stl" scale="0.001 0.001 0.001"/>
    </geometry>
    <material name="brown"/>
  </visual>
  <collision>
    <origin xyz="-0.1 -0.0 -0.154" rpy="0 0 0"/>
    <geometry>
      <mesh filename="file://$(find kc_vision_description)/meshes/gps_v1_1.stl" scale="0.001 0.001 0.001"/>
    </geometry>
  </collision>
</link>

<gazebo reference="base_link">
    <mu1 value="0.0"/>
    <mu2 value="0.0"/>
</gazebo>


<joint name="Rigid 1" type="fixed">
  <origin xyz="0.13 0.0 0.099" rpy="0 0 0"/>
  <parent link="base_link"/>
  <child link="lidar_link"/>
</joint>

<joint name="Rigid 2" type="fixed">
  <origin xyz="0.16 0.0 0.089" rpy="0 0 0"/>
  <parent link="base_link"/>
  <child link="camera_link"/>
</joint>

<joint name="Rigid 3" type="fixed">
  <origin xyz="-0.138 0.156 0.044" rpy="0 0 0"/>
  <parent link="base_link"/>
  <child link="left_A7_-_DC_Geared_Motor_1"/>
</joint>

<joint name="Rigid 4" type="fixed">
  <origin xyz="-0.138 -0.156 0.044" rpy="0 0 0"/>
  <parent link="base_link"/>
  <child link="A7_-_DC_Geared_Motor_v1__1__1"/>
</joint>

<joint name="rear_left_wheel_joint" type="continuous">
  <origin xyz="0.0 -0.0368 -0.007" rpy="0 0 0"/>
  <parent link="A7_-_DC_Geared_Motor_v1__1__1"/>
  <child link="Wheel_Rim_s_v1_1"/>
  <axis xyz="-0.0 1.0 0.0"/>
</joint>

<joint name="rear_right_wheel_joint" type="continuous">
  <origin xyz="0.0 0.0368 -0.007" rpy="0 0 0"/>
  <parent link="left_A7_-_DC_Geared_Motor_1"/>
  <child link="Wheel_Rim_s_v1__1__1"/>
  <axis xyz="0.0 1.0 -0.0"/>
</joint>

<joint name="Rigid 7" type="fixed">
  <origin xyz="0.0 -0.0115 0.0" rpy="0 0 0"/>
  <parent link="Wheel_Rim_s_v1_1"/>
  <child link="Wheel_Tire_ipt_v1_1"/>
</joint>

<joint name="Rigid 8" type="fixed">
  <origin xyz="0.0 0.0115 0.0" rpy="0 0 0"/>
  <parent link="Wheel_Rim_s_v1__1__1"/>
  <child link="Wheel_Tire_ipt_v1__1__1"/>
</joint>

<joint name="Rigid 9" type="fixed">
  <origin xyz="-0.165 0.0 0.154" rpy="0 0 0"/>
  <parent link="base_link"/>
  <child link="imu_link"/>
</joint>

<joint name="Rigid 10" type="fixed">
  <origin xyz="0.1 0.0 0.154" rpy="0 0 0"/>
  <parent link="base_link"/>
  <child link="gps_link"/>
</joint>

</robot>
